# 在程序运行的过程中，如果发生了错误，可以事先约定返回一个错误代码，这样，就可以知道是否有错，以及出错的原因。在操作系统提供的调用中，返回错误码非常常见。比如打开文件的函数open()，成功时返回文件描述符（就是一个整数），出错时返回-1。

# 用错误码来表示是否出错十分不便，因为函数本身应该返回的正常结果和错误码混在一起，造成调用者必须用大量的代码来判断是否出错：
def foo():
    r=some_function()
    if r==(-1):
        return (-1)
    #do something
    return r

def bar():
    r=foo()
    if r==(-1):
        print('Error')
    else:
        pass
#try

try:
    print('try...')
    r=10/0
    print('result: ',r)
except ZeroDivisionError as e:
    print('except:',e)
finally:
    print('finally...')
print('End the first try: ignore the wrong message 10/0\n')
# 当我们认为某些代码可能会出错时，就可以用try来运行这段代码，如果执行出错，则后续代码不会继续执行，而是直接跳转至错误处理代码，即except语句块，执行完except后，如果有finally语句块，则执行finally语句块，至此，执行完毕。
try:
    print('try...')
    r=10/2
    print('result: ',r)
except ZeroDivisionError as e:
    print('except:',e)
finally:
    print('finally...')
print('End the second try: run the right message 10/2\n')

# 由于没有错误发生，所以except语句块不会被执行，但是finally如果有，则一定会被执行（可以没有finally语句）。

# 你还可以猜测，错误应该有很多种类，如果发生了不同类型的错误，应该由不同的except语句块处理。没错，可以有多个except来捕获不同类型的错误：
try:
    print('try...')
    r = 10 / int('a')
    print('result:', r)
except ValueError as e:
    print('ValueError:', e)
except ZeroDivisionError as e:
    print('ZeroDivisionError:', e)
finally:
    print('finally...')
print('END')
# int()函数可能会抛出ValueError，所以我们用一个except捕获ValueError，用另一个except捕获ZeroDivisionError。

# 此外，如果没有错误发生，可以在except语句块后面加一个else，当没有错误发生时，会自动执行else语句
try:
    print('try...')
    r = 10 / int('2')
    print('result:', r)
except ValueError as e:
    print('ValueError:', e)
except ZeroDivisionError as e:
    print('ZeroDivisionError:', e)
else:
    print('no error!')
finally:
    print('finally...')
print('END')

# Python的错误其实也是class，所有的错误类型都继承自BaseException，所以在使用except时需要注意的是，它不但捕获该类型的错误，还把其子类也“一网打尽”。比如：
# try:
#     foo()
# except ValueError as e:
#     print('ValueError')
# except UnicodeError as e:
#     print('UnicodeError')
# 第二个except永远也捕获不到UnicodeError，因为UnicodeError是ValueError的子类，如果有，也被第一个except给捕获了。
#Python所有的错误都是从BaseException类派生的，常见的错误类型和继承关系看这里：

# Exception hierarchy
# The class hierarchy for built-in exceptions is:

# BaseException
#  +-- SystemExit
#  +-- KeyboardInterrupt
#  +-- GeneratorExit
#  +-- Exception
#       +-- StopIteration
#       +-- StopAsyncIteration
#       +-- ArithmeticError
#       |    +-- FloatingPointError
#       |    +-- OverflowError
#       |    +-- ZeroDivisionError
#       +-- AssertionError
#       +-- AttributeError
#       +-- BufferError
#       +-- EOFError
#       +-- ImportError
#       |    +-- ModuleNotFoundError
#       +-- LookupError
#       |    +-- IndexError
#       |    +-- KeyError
#       +-- MemoryError
#       +-- NameError
#       |    +-- UnboundLocalError
#       +-- OSError
#       |    +-- BlockingIOError
#       |    +-- ChildProcessError
#       |    +-- ConnectionError
#       |    |    +-- BrokenPipeError
#       |    |    +-- ConnectionAbortedError
#       |    |    +-- ConnectionRefusedError
#       |    |    +-- ConnectionResetError
#       |    +-- FileExistsError
#       |    +-- FileNotFoundError
#       |    +-- InterruptedError
#       |    +-- IsADirectoryError
#       |    +-- NotADirectoryError
#       |    +-- PermissionError
#       |    +-- ProcessLookupError
#       |    +-- TimeoutError
#       +-- ReferenceError
#       +-- RuntimeError
#       |    +-- NotImplementedError
#       |    +-- RecursionError
#       +-- SyntaxError
#       |    +-- IndentationError
#       |         +-- TabError
#       +-- SystemError
#       +-- TypeError
#       +-- ValueError
#       |    +-- UnicodeError
#       |         +-- UnicodeDecodeError
#       |         +-- UnicodeEncodeError
#       |         +-- UnicodeTranslateError
#       +-- Warning
#            +-- DeprecationWarning
#            +-- PendingDeprecationWarning
#            +-- RuntimeWarning
#            +-- SyntaxWarning
#            +-- UserWarning
#            +-- FutureWarning
#            +-- ImportWarning
#            +-- UnicodeWarning
#            +-- BytesWarning
#            +-- ResourceWarning

# 使用try...except捕获错误可以跨越多层调用，比如函数main()调用foo()，foo()调用bar()，结果bar()出错了，这时，只要main()捕获到了，就可以处理：
def foo(s):
    return 10 / int(s)

def bar(s):
    return foo(s) * 2

def main():
    try:
        bar('0')
    except Exception as e:
        print('Error:', e)
    finally:
        print('foo bar mai finally...')

# 也就是说，不需要在每个可能出错的地方去捕获错误，只要在合适的层次去捕获错误就可以了。这样一来，就大大减少了写try...except...finally的麻烦。

#调用栈
# 如果错误没有被捕获，它就会一直往上抛，最后被Python解释器捕获，打印一个错误信息，然后程序退出。来看看err.py：
#err.py:
def foo(s):
    return 10/int(s)
def bar(s):
    return foo(s)*2
def main():
    bar('0')

main()
#出现以下错误：
Traceback (most recent call last):#这是错误的追踪信息
  File "ex39错误处理.py", line 175, in <module>
    main()#   调用main()出错了，在代码文件err.py的第175行代码，但原因是第173行：
  File "ex39错误处理.py", line 173, in main
    bar('0')#调用bar('0')出错了，在代码文件err.py的第173行代码，但原因是第171行：
  File "ex39错误处理.py", line 171, in bar
    return foo(s)*2#原因是return foo(s) * 2这个语句出错了，但这还不是最终原因，继续往下看：
  File "ex39错误处理.py", line 169, in foo
    return 10/int(s)#因是return 10 / int(s)这个语句出错了，这是错误产生的源头，因为下面打印了：
ZeroDivisionError: division by zero
#根据错误类型ZeroDivisionError，我们判断，int(s)本身并没有出错，但是int(s)返回0，在计算10 / 0时出错，至此，找到错误源头
